<?xml version="1.0"?>
<robot name="ackermann_robot" xmlns:xacro="http://www.ros.org/wiki/xacro">

  <!-- BX-S40 Parameters -->
  <xacro:property name="body_length" value="0.9"/>
  <xacro:property name="body_width" value="0.6"/>
  <xacro:property name="body_height" value="0.4"/>
  <xacro:property name="body_density" value="150.0"/>
  <xacro:property name="wheel_radius" value="0.16"/>
  <xacro:property name="wheel_width" value="0.08"/>
  <xacro:property name="wheel_density" value="900.0"/>
  <xacro:property name="max_steering_angle" value="0.5236"/>
  <xacro:property name="max_steering_angular_velocity" value="1.570796"/>
  <xacro:property name="max_steering_effort" value="100.0"/>
  <xacro:property name="max_velocity" value="1.4"/>
  <xacro:property name="max_effort" value="100.0"/>
  <xacro:property name="PI" value="3.14159265"/>

  <!-- Derived properties -->
  <xacro:property name="body_mass" value="${body_density * body_length * body_height * body_width}"/>
  <xacro:property name="body_inertia_x" value="${1.0/12.0 * body_mass * (body_height*body_height + body_width*body_width)}"/>
  <xacro:property name="body_inertia_y" value="${1.0/12.0 * body_mass * (body_length*body_length + body_height*body_height)}"/>
  <xacro:property name="body_inertia_z" value="${1.0/12.0 * body_mass * (body_length*body_length + body_width*body_width)}"/>
  <xacro:property name="wheel_separation" value="${body_width + wheel_width}"/>
  <xacro:property name="wheel_offset" value="${body_length/2 - wheel_radius}"/>
  <xacro:property name="wheel_mass" value="${wheel_density * PI * wheel_radius * wheel_radius * wheel_width}"/>
  <xacro:property name="wheel_inertia_x" value="${1.0/12.0 * wheel_mass * (3*wheel_radius*wheel_radius + wheel_width*wheel_width)}"/>
  <xacro:property name="wheel_inertia_y" value="${1.0/12.0 * wheel_mass * (3*wheel_radius*wheel_radius + wheel_width*wheel_width)}"/>
  <xacro:property name="wheel_inertia_z" value="${1.0/2.0 * wheel_mass * wheel_radius * wheel_radius}"/>
  <xacro:property name="max_wheel_angular_velocity" value="${max_velocity / wheel_radius}"/>

  <!-- ========== Links ========== -->

  <!-- Body Link -->
  <link name="body_link">
    <visual>
      <origin xyz="0 0 0" rpy="0 0 0"/>
      <geometry>
        <box size="${body_length} ${body_width} ${body_height}"/>
      </geometry>
      <material name="body_material">
        <color rgba="0.25 0.25 0.25 1.0"/>
      </material>
    </visual>
    <collision>
      <origin xyz="0 0 0" rpy="0 0 0"/>
      <geometry>
        <box size="${body_length} ${body_width} ${body_height}"/>
      </geometry>
    </collision>
    <inertial>
      <mass value="${body_mass}"/>
      <inertia ixx="${body_inertia_x}" ixy="0.0" ixz="0.0" iyy="${body_inertia_y}" iyz="0.0" izz="${body_inertia_z}"/>
      <origin xyz="0 0 0" rpy="0 0 0"/>
    </inertial>
  </link>

  <!-- Front Left Steering Link -->
  <link name="front_left_steering_link">
    <visual>
      <origin xyz="0 0 0" rpy="1.570795 0 0"/>
      <geometry>
        <cylinder length="0.001" radius="0.01"/>
      </geometry>
      <material name="steering_material">
        <color rgba="0.5 0.5 0.5 1.0"/>
      </material>
    </visual>
    <collision>
      <origin xyz="0 0 0" rpy="1.570795 0 0"/>
      <geometry>
        <cylinder length="0.001" radius="0.01"/>
      </geometry>
    </collision>
    <inertial>
      <mass value="0.01"/>
      <inertia ixx="0.0" ixy="0.0" ixz="0.0" iyy="0.0" iyz="0.0" izz="0.0"/>
      <origin xyz="0 0 0" rpy="0 0 0"/>
    </inertial>
  </link>

  <!-- Front Left Wheel Link -->
  <link name="front_left_wheel_link">
    <visual>
      <origin xyz="0 0 0" rpy="1.570795 0 0"/>
      <geometry>
        <cylinder radius="${wheel_radius}" length="${wheel_width}"/>
      </geometry>
      <material name="wheel_material">
        <color rgba="0.0 0.0 0.0 1.0"/>
      </material>
    </visual>
    <!-- Rotation marker stripe (visual only) -->
    <visual>
      <origin xyz="${wheel_radius} 0 0" rpy="0 1.570795 0"/>
      <geometry>
        <box size="${wheel_width * 0.8} ${wheel_radius * 0.3} ${wheel_radius * 0.15}"/>
      </geometry>
      <material name="stripe_material_fl">
        <color rgba="1.0 0.0 0.0 1.0"/>
      </material>
    </visual>
    <collision>
      <origin xyz="0 0 0" rpy="1.570795 0 0"/>
      <geometry>
        <cylinder radius="${wheel_radius}" length="${wheel_width}"/>
      </geometry>
    </collision>
    <inertial>
      <mass value="${wheel_mass}"/>
      <inertia ixx="${wheel_inertia_x}" ixy="0.0" ixz="0.0" iyy="${wheel_inertia_y}" iyz="0.0" izz="${wheel_inertia_z}"/>
      <origin xyz="0 0 0" rpy="0 0 0"/>
    </inertial>
  </link>

  <!-- Front Right Steering Link -->
  <link name="front_right_steering_link">
    <visual>
      <origin xyz="0 0 0" rpy="1.570795 0 0"/>
      <geometry>
        <cylinder length="0.001" radius="0.01"/>
      </geometry>
      <material name="steering_material">
        <color rgba="0.5 0.5 0.5 1.0"/>
      </material>
    </visual>
    <collision>
      <origin xyz="0 0 0" rpy="1.570795 0 0"/>
      <geometry>
        <cylinder length="0.001" radius="0.01"/>
      </geometry>
    </collision>
    <inertial>
      <mass value="0.01"/>
      <inertia ixx="0.0" ixy="0.0" ixz="0.0" iyy="0.0" iyz="0.0" izz="0.0"/>
      <origin xyz="0 0 0" rpy="0 0 0"/>
    </inertial>
  </link>

  <!-- Front Right Wheel Link -->
  <link name="front_right_wheel_link">
    <visual>
      <origin xyz="0 0 0" rpy="1.570795 0 0"/>
      <geometry>
        <cylinder radius="${wheel_radius}" length="${wheel_width}"/>
      </geometry>
      <material name="wheel_material">
        <color rgba="0.0 0.0 0.0 1.0"/>
      </material>
    </visual>
    <!-- Rotation marker stripe (visual only) -->
    <visual>
      <origin xyz="${wheel_radius} 0 0" rpy="0 1.570795 0"/>
      <geometry>
        <box size="${wheel_width * 0.8} ${wheel_radius * 0.3} ${wheel_radius * 0.15}"/>
      </geometry>
      <material name="stripe_material_fr">
        <color rgba="1.0 0.0 0.0 1.0"/>
      </material>
    </visual>
    <collision>
      <origin xyz="0 0 0" rpy="1.570795 0 0"/>
      <geometry>
        <cylinder radius="${wheel_radius}" length="${wheel_width}"/>
      </geometry>
    </collision>
    <inertial>
      <mass value="${wheel_mass}"/>
      <inertia ixx="${wheel_inertia_x}" ixy="0.0" ixz="0.0" iyy="${wheel_inertia_y}" iyz="0.0" izz="${wheel_inertia_z}"/>
      <origin xyz="0 0 0" rpy="0 0 0"/>
    </inertial>
  </link>

  <!-- Rear Left Wheel Link -->
  <link name="rear_left_wheel_link">
    <visual>
      <origin xyz="0 0 0" rpy="1.570795 0 0"/>
      <geometry>
        <cylinder radius="${wheel_radius}" length="${wheel_width}"/>
      </geometry>
      <material name="wheel_material">
        <color rgba="0.0 0.0 0.0 1.0"/>
      </material>
    </visual>
    <!-- Rotation marker stripe (visual only) -->
    <visual>
      <origin xyz="${wheel_radius} 0 0" rpy="0 1.570795 0"/>
      <geometry>
        <box size="${wheel_width * 0.8} ${wheel_radius * 0.3} ${wheel_radius * 0.15}"/>
      </geometry>
      <material name="stripe_material_rl">
        <color rgba="1.0 0.0 0.0 1.0"/>
      </material>
    </visual>
    <collision>
      <origin xyz="0 0 0" rpy="1.570795 0 0"/>
      <geometry>
        <cylinder radius="${wheel_radius}" length="${wheel_width}"/>
      </geometry>
    </collision>
    <inertial>
      <mass value="${wheel_mass}"/>
      <inertia ixx="${wheel_inertia_x}" ixy="0.0" ixz="0.0" iyy="${wheel_inertia_y}" iyz="0.0" izz="${wheel_inertia_z}"/>
      <origin xyz="0 0 0" rpy="0 0 0"/>
    </inertial>
  </link>

  <!-- Rear Right Wheel Link -->
  <link name="rear_right_wheel_link">
    <visual>
      <origin xyz="0 0 0" rpy="1.570795 0 0"/>
      <geometry>
        <cylinder radius="${wheel_radius}" length="${wheel_width}"/>
      </geometry>
      <material name="wheel_material">
        <color rgba="0.0 0.0 0.0 1.0"/>
      </material>
    </visual>
    <!-- Rotation marker stripe (visual only) -->
    <visual>
      <origin xyz="${wheel_radius} 0 0" rpy="0 1.570795 0"/>
      <geometry>
        <box size="${wheel_width * 0.8} ${wheel_radius * 0.3} ${wheel_radius * 0.15}"/>
      </geometry>
      <material name="stripe_material_rr">
        <color rgba="1.0 0.0 0.0 1.0"/>
      </material>
    </visual>
    <collision>
      <origin xyz="0 0 0" rpy="1.570795 0 0"/>
      <geometry>
        <cylinder radius="${wheel_radius}" length="${wheel_width}"/>
      </geometry>
    </collision>
    <inertial>
      <mass value="${wheel_mass}"/>
      <inertia ixx="${wheel_inertia_x}" ixy="0.0" ixz="0.0" iyy="${wheel_inertia_y}" iyz="0.0" izz="${wheel_inertia_z}"/>
      <origin xyz="0 0 0" rpy="0 0 0"/>
    </inertial>
  </link>

  <!-- ========== Joints ========== -->

  <!-- Front Left Steering Joint (position controlled, Z-axis) -->
  <joint name="front_left_steering_joint" type="revolute">
    <origin xyz="${wheel_offset} ${wheel_separation/2} -${wheel_radius/2}" rpy="0 0 0"/>
    <parent link="body_link"/>
    <child link="front_left_steering_link"/>
    <axis xyz="0 0 1"/>
    <limit effort="${max_steering_effort}" lower="${-max_steering_angle}" upper="${max_steering_angle}" velocity="${max_steering_angular_velocity}"/>
    <dynamics damping="0.01" friction="0.01"/>
  </joint>

  <!-- Front Left Wheel Joint (passive, Y-axis) -->
  <joint name="front_left_wheel_joint" type="continuous">
    <origin xyz="0 0 0" rpy="0 0 0"/>
    <parent link="front_left_steering_link"/>
    <child link="front_left_wheel_link"/>
    <axis xyz="0 1 0"/>
    <limit effort="${max_effort}" velocity="${max_wheel_angular_velocity}"/>
    <dynamics damping="0.01" friction="0.01"/>
  </joint>

  <!-- Front Right Steering Joint (position controlled, Z-axis) -->
  <joint name="front_right_steering_joint" type="revolute">
    <origin xyz="${wheel_offset} ${-wheel_separation/2} -${wheel_radius/2}" rpy="0 0 0"/>
    <parent link="body_link"/>
    <child link="front_right_steering_link"/>
    <axis xyz="0 0 1"/>
    <limit effort="${max_steering_effort}" lower="${-max_steering_angle}" upper="${max_steering_angle}" velocity="${max_steering_angular_velocity}"/>
    <dynamics damping="0.01" friction="0.01"/>
  </joint>

  <!-- Front Right Wheel Joint (passive, Y-axis) -->
  <joint name="front_right_wheel_joint" type="continuous">
    <origin xyz="0 0 0" rpy="0 0 0"/>
    <parent link="front_right_steering_link"/>
    <child link="front_right_wheel_link"/>
    <axis xyz="0 1 0"/>
    <limit effort="${max_effort}" velocity="${max_wheel_angular_velocity}"/>
    <dynamics damping="0.01" friction="0.01"/>
  </joint>

  <!-- Rear Left Wheel Joint (velocity controlled, Y-axis) -->
  <joint name="rear_left_wheel_joint" type="continuous">
    <origin xyz="-${wheel_offset} ${wheel_separation/2} -${wheel_radius/2}" rpy="0 0 0"/>
    <parent link="body_link"/>
    <child link="rear_left_wheel_link"/>
    <axis xyz="0 1 0"/>
    <limit effort="${max_effort}" velocity="${max_wheel_angular_velocity}"/>
    <dynamics damping="0.01" friction="0.01"/>
  </joint>

  <!-- Rear Right Wheel Joint (velocity controlled, Y-axis) -->
  <joint name="rear_right_wheel_joint" type="continuous">
    <origin xyz="-${wheel_offset} ${-wheel_separation/2} -${wheel_radius/2}" rpy="0 0 0"/>
    <parent link="body_link"/>
    <child link="rear_right_wheel_link"/>
    <axis xyz="0 1 0"/>
    <limit effort="${max_effort}" velocity="${max_wheel_angular_velocity}"/>
    <dynamics damping="0.01" friction="0.01"/>
  </joint>

  <!-- ========== Gazebo Surface Friction ========== -->
  <gazebo reference="body_link">
    <mu1>0.0001</mu1>
    <mu2>0.0001</mu2>
  </gazebo>
  <gazebo reference="front_left_wheel_link">
    <mu1>1.0</mu1>
    <mu2>1.0</mu2>
  </gazebo>
  <gazebo reference="front_right_wheel_link">
    <mu1>1.0</mu1>
    <mu2>1.0</mu2>
  </gazebo>
  <gazebo reference="rear_left_wheel_link">
    <mu1>1.0</mu1>
    <mu2>1.0</mu2>
  </gazebo>
  <gazebo reference="rear_right_wheel_link">
    <mu1>1.0</mu1>
    <mu2>1.0</mu2>
  </gazebo>

  <!-- ========== ros2_control ========== -->
  <ros2_control name="control" type="system">
    <hardware>
      <plugin>gz_ros2_control/GazeboSimSystem</plugin>
    </hardware>

    <joint name="front_left_steering_joint">
      <command_interface name="position">
        <param name="min">${-max_steering_angle}</param>
        <param name="max">${max_steering_angle}</param>
      </command_interface>
      <state_interface name="position"/>
      <state_interface name="velocity"/>
      <state_interface name="effort"/>
    </joint>

    <joint name="front_right_steering_joint">
      <command_interface name="position">
        <param name="min">${-max_steering_angle}</param>
        <param name="max">${max_steering_angle}</param>
      </command_interface>
      <state_interface name="position"/>
      <state_interface name="velocity"/>
      <state_interface name="effort"/>
    </joint>

    <joint name="rear_left_wheel_joint">
      <command_interface name="velocity">
        <param name="min">${-max_wheel_angular_velocity}</param>
        <param name="max">${max_wheel_angular_velocity}</param>
      </command_interface>
      <state_interface name="position"/>
      <state_interface name="velocity"/>
      <state_interface name="effort"/>
    </joint>

    <joint name="rear_right_wheel_joint">
      <command_interface name="velocity">
        <param name="min">${-max_wheel_angular_velocity}</param>
        <param name="max">${max_wheel_angular_velocity}</param>
      </command_interface>
      <state_interface name="position"/>
      <state_interface name="velocity"/>
      <state_interface name="effort"/>
    </joint>
  </ros2_control>

  <!-- ========== Gazebo Plugins ========== -->
  <gazebo>
    <plugin filename="gz-sim-joint-state-publisher-system" name="gz::sim::systems::JointStatePublisher">
      <topic>joint_states</topic>
      <joint_name>front_left_steering_joint</joint_name>
      <joint_name>front_right_steering_joint</joint_name>
      <joint_name>front_left_wheel_joint</joint_name>
      <joint_name>front_right_wheel_joint</joint_name>
      <joint_name>rear_left_wheel_joint</joint_name>
      <joint_name>rear_right_wheel_joint</joint_name>
    </plugin>

    <plugin filename="gz_ros2_control-system" name="gz_ros2_control::GazeboSimROS2ControlPlugin">
      <parameters>$(find ackermann_control)/config/gz_ros2_control.yaml</parameters>
    </plugin>

    <plugin filename="gz-sim-imu-system" name="gz::sim::systems::Imu">
    </plugin>

    <plugin filename="gz-sim-odometry-publisher-system" name="gz::sim::systems::OdometryPublisher">
      <odom_frame>odom</odom_frame>
      <robot_base_frame>body_link</robot_base_frame>
      <odom_topic>/odom</odom_topic>
      <dimensions>3</dimensions>
    </plugin>
  </gazebo>

  <!-- ========== Sensors ========== -->

  <!-- 2D LiDAR on body_link -->
  <gazebo reference="body_link">
    <sensor name="lidar" type="gpu_lidar">
      <pose>0 0 0.22 0 0 0</pose>
      <topic>/scan</topic>
      <update_rate>10</update_rate>
      <lidar>
        <scan>
          <horizontal>
            <samples>3200</samples>
            <resolution>1</resolution>
            <min_angle>0.0</min_angle>
            <max_angle>6.28318</max_angle>
          </horizontal>
        </scan>
        <range>
          <min>0.15</min>
          <max>18.0</max>
        </range>
      </lidar>
      <visualize>true</visualize>
    </sensor>

    <!-- IMU on body_link -->
    <sensor name="imu_sensor" type="imu">
      <always_on>1</always_on>
      <update_rate>100</update_rate>
      <visualize>true</visualize>
      <topic>/imu</topic>
      <imu>
        <angular_velocity>
          <x><noise type="gaussian"><mean>0.0</mean><stddev>0.00017</stddev></noise></x>
          <y><noise type="gaussian"><mean>0.0</mean><stddev>0.00017</stddev></noise></y>
          <z><noise type="gaussian"><mean>0.0</mean><stddev>0.00017</stddev></noise></z>
        </angular_velocity>
        <linear_acceleration>
          <x><noise type="gaussian"><mean>0.0</mean><stddev>0.001</stddev></noise></x>
          <y><noise type="gaussian"><mean>0.0</mean><stddev>0.001</stddev></noise></y>
          <z><noise type="gaussian"><mean>0.0</mean><stddev>0.001</stddev></noise></z>
        </linear_acceleration>
      </imu>
    </sensor>
  </gazebo>

</robot>
